2021-12-15 10:43:40 WARNING (Recorder) [homeassistant.components.recorder.util] The system could not validate that the sqlite3 database at //config/home-assistant_v2.db was shutdown cleanly
2021-12-15 10:43:56 WARNING (MainThread) [homeassistant.config_entries] Config entry 'M5' for upnp integration not ready yet: Cannot connect to host 2806:1000:8000:36cf:423f:8cff:feb2:f6e8:1900 ssl:default [Network unreachable]; Retrying in background
2021-12-15 10:44:04 WARNING (MainThread) [homeassistant.config_entries] Config entry 'Huawei IGD' for upnp integration not ready yet; Retrying in background
2021-12-15 10:47:04 ERROR (MainThread) [aiohttp.server] Error handling request
Traceback (most recent call last):
  File "/usr/local/lib/python3.9/site-packages/aiohttp/web_protocol.py", line 435, in _handle_request
    resp = await request_handler(request)
  File "/usr/local/lib/python3.9/site-packages/aiohttp/web_app.py", line 504, in _handle
    resp = await handler(request)
  File "/usr/local/lib/python3.9/site-packages/aiohttp/web_middlewares.py", line 117, in impl
    return await handler(request)
  File "/usr/src/homeassistant/homeassistant/components/http/security_filter.py", line 60, in security_filter_middleware
    return await handler(request)
  File "/usr/src/homeassistant/homeassistant/components/http/forwarded.py", line 98, in forwarded_middleware
    return await handler(request)
  File "/usr/src/homeassistant/homeassistant/components/http/request_context.py", line 28, in request_context_middleware
    return await handler(request)
  File "/usr/src/homeassistant/homeassistant/components/http/ban.py", line 78, in ban_middleware
    return await handler(request)
  File "/usr/src/homeassistant/homeassistant/components/http/auth.py", line 181, in auth_middleware
    return await handler(request)
  File "/usr/src/homeassistant/homeassistant/components/http/view.py", line 137, in handle
    result = await result
  File "/usr/src/homeassistant/homeassistant/components/config/config_entries.py", line 215, in post
    return await super().post(request, flow_id)
  File "/usr/src/homeassistant/homeassistant/components/http/data_validator.py", line 62, in wrapper
    result = await method(view, request, *args, **kwargs)
  File "/usr/src/homeassistant/homeassistant/helpers/data_entry_flow.py", line 110, in post
    result = await self._flow_mgr.async_configure(flow_id, data)
  File "/usr/src/homeassistant/homeassistant/data_entry_flow.py", line 252, in async_configure
    result = await self._async_handle_step(flow, cur_step["step_id"], user_input)
  File "/usr/src/homeassistant/homeassistant/data_entry_flow.py", line 325, in _async_handle_step
    result: FlowResult = await getattr(flow, method)(user_input)
  File "/usr/src/homeassistant/homeassistant/components/upnp/config_flow.py", line 295, in async_step_init
    coordinator = self.hass.data[DOMAIN][self.config_entry.entry_id]
KeyError: '6fe907fbd696a41bf919cf5ca58dab68'
2021-12-15 10:47:05 ERROR (MainThread) [aiohttp.server] Error handling request
Traceback (most recent call last):
  File "/usr/local/lib/python3.9/site-packages/aiohttp/web_protocol.py", line 435, in _handle_request
    resp = await request_handler(request)
  File "/usr/local/lib/python3.9/site-packages/aiohttp/web_app.py", line 504, in _handle
    resp = await handler(request)
  File "/usr/local/lib/python3.9/site-packages/aiohttp/web_middlewares.py", line 117, in impl
    return await handler(request)
  File "/usr/src/homeassistant/homeassistant/components/http/security_filter.py", line 60, in security_filter_middleware
    return await handler(request)
  File "/usr/src/homeassistant/homeassistant/components/http/forwarded.py", line 98, in forwarded_middleware
    return await handler(request)
  File "/usr/src/homeassistant/homeassistant/components/http/request_context.py", line 28, in request_context_middleware
    return await handler(request)
  File "/usr/src/homeassistant/homeassistant/components/http/ban.py", line 78, in ban_middleware
    return await handler(request)
  File "/usr/src/homeassistant/homeassistant/components/http/auth.py", line 181, in auth_middleware
    return await handler(request)
  File "/usr/src/homeassistant/homeassistant/components/http/view.py", line 137, in handle
    result = await result
  File "/usr/src/homeassistant/homeassistant/components/config/config_entries.py", line 215, in post
    return await super().post(request, flow_id)
  File "/usr/src/homeassistant/homeassistant/components/http/data_validator.py", line 62, in wrapper
    result = await method(view, request, *args, **kwargs)
  File "/usr/src/homeassistant/homeassistant/helpers/data_entry_flow.py", line 110, in post
    result = await self._flow_mgr.async_configure(flow_id, data)
  File "/usr/src/homeassistant/homeassistant/data_entry_flow.py", line 252, in async_configure
    result = await self._async_handle_step(flow, cur_step["step_id"], user_input)
  File "/usr/src/homeassistant/homeassistant/data_entry_flow.py", line 325, in _async_handle_step
    result: FlowResult = await getattr(flow, method)(user_input)
  File "/usr/src/homeassistant/homeassistant/components/upnp/config_flow.py", line 295, in async_step_init
    coordinator = self.hass.data[DOMAIN][self.config_entry.entry_id]
KeyError: '6fe907fbd696a41bf919cf5ca58dab68'
2021-12-15 10:49:14 ERROR (MainThread) [aiohttp.server] Error handling request
Traceback (most recent call last):
  File "/usr/local/lib/python3.9/site-packages/aiohttp/web_protocol.py", line 435, in _handle_request
    resp = await request_handler(request)
  File "/usr/local/lib/python3.9/site-packages/aiohttp/web_app.py", line 504, in _handle
    resp = await handler(request)
  File "/usr/local/lib/python3.9/site-packages/aiohttp/web_middlewares.py", line 117, in impl
    return await handler(request)
  File "/usr/src/homeassistant/homeassistant/components/http/security_filter.py", line 60, in security_filter_middleware
    return await handler(request)
  File "/usr/src/homeassistant/homeassistant/components/http/forwarded.py", line 98, in forwarded_middleware
    return await handler(request)
  File "/usr/src/homeassistant/homeassistant/components/http/request_context.py", line 28, in request_context_middleware
    return await handler(request)
  File "/usr/src/homeassistant/homeassistant/components/http/ban.py", line 78, in ban_middleware
    return await handler(request)
  File "/usr/src/homeassistant/homeassistant/components/http/auth.py", line 181, in auth_middleware
    return await handler(request)
  File "/usr/src/homeassistant/homeassistant/components/http/view.py", line 137, in handle
    result = await result
  File "/usr/src/homeassistant/homeassistant/components/config/config_entries.py", line 215, in post
    return await super().post(request, flow_id)
  File "/usr/src/homeassistant/homeassistant/components/http/data_validator.py", line 62, in wrapper
    result = await method(view, request, *args, **kwargs)
  File "/usr/src/homeassistant/homeassistant/helpers/data_entry_flow.py", line 110, in post
    result = await self._flow_mgr.async_configure(flow_id, data)
  File "/usr/src/homeassistant/homeassistant/data_entry_flow.py", line 252, in async_configure
    result = await self._async_handle_step(flow, cur_step["step_id"], user_input)
  File "/usr/src/homeassistant/homeassistant/data_entry_flow.py", line 325, in _async_handle_step
    result: FlowResult = await getattr(flow, method)(user_input)
  File "/usr/src/homeassistant/homeassistant/components/upnp/config_flow.py", line 295, in async_step_init
    coordinator = self.hass.data[DOMAIN][self.config_entry.entry_id]
KeyError: '6fe907fbd696a41bf919cf5ca58dab68'
2021-12-15 10:51:35 ERROR (MainThread) [aiohttp.server] Error handling request
Traceback (most recent call last):
  File "/usr/local/lib/python3.9/site-packages/aiohttp/web_protocol.py", line 435, in _handle_request
    resp = await request_handler(request)
  File "/usr/local/lib/python3.9/site-packages/aiohttp/web_app.py", line 504, in _handle
    resp = await handler(request)
  File "/usr/local/lib/python3.9/site-packages/aiohttp/web_middlewares.py", line 117, in impl
    return await handler(request)
  File "/usr/src/homeassistant/homeassistant/components/http/security_filter.py", line 60, in security_filter_middleware
    return await handler(request)
  File "/usr/src/homeassistant/homeassistant/components/http/forwarded.py", line 98, in forwarded_middleware
    return await handler(request)
  File "/usr/src/homeassistant/homeassistant/components/http/request_context.py", line 28, in request_context_middleware
    return await handler(request)
  File "/usr/src/homeassistant/homeassistant/components/http/ban.py", line 78, in ban_middleware
    return await handler(request)
  File "/usr/src/homeassistant/homeassistant/components/http/auth.py", line 181, in auth_middleware
    return await handler(request)
  File "/usr/src/homeassistant/homeassistant/components/http/view.py", line 137, in handle
    result = await result
  File "/usr/src/homeassistant/homeassistant/components/config/config_entries.py", line 215, in post
    return await super().post(request, flow_id)
  File "/usr/src/homeassistant/homeassistant/components/http/data_validator.py", line 62, in wrapper
    result = await method(view, request, *args, **kwargs)
  File "/usr/src/homeassistant/homeassistant/helpers/data_entry_flow.py", line 110, in post
    result = await self._flow_mgr.async_configure(flow_id, data)
  File "/usr/src/homeassistant/homeassistant/data_entry_flow.py", line 252, in async_configure
    result = await self._async_handle_step(flow, cur_step["step_id"], user_input)
  File "/usr/src/homeassistant/homeassistant/data_entry_flow.py", line 325, in _async_handle_step
    result: FlowResult = await getattr(flow, method)(user_input)
  File "/usr/src/homeassistant/homeassistant/components/upnp/config_flow.py", line 295, in async_step_init
    coordinator = self.hass.data[DOMAIN][self.config_entry.entry_id]
KeyError: '6fe907fbd696a41bf919cf5ca58dab68'
2021-12-15 10:53:23 ERROR (MainThread) [aiohttp.server] Error handling request
Traceback (most recent call last):
  File "/usr/local/lib/python3.9/site-packages/aiohttp/web_protocol.py", line 435, in _handle_request
    resp = await request_handler(request)
  File "/usr/local/lib/python3.9/site-packages/aiohttp/web_app.py", line 504, in _handle
    resp = await handler(request)
  File "/usr/local/lib/python3.9/site-packages/aiohttp/web_middlewares.py", line 117, in impl
    return await handler(request)
  File "/usr/src/homeassistant/homeassistant/components/http/security_filter.py", line 60, in security_filter_middleware
    return await handler(request)
  File "/usr/src/homeassistant/homeassistant/components/http/forwarded.py", line 98, in forwarded_middleware
    return await handler(request)
  File "/usr/src/homeassistant/homeassistant/components/http/request_context.py", line 28, in request_context_middleware
    return await handler(request)
  File "/usr/src/homeassistant/homeassistant/components/http/ban.py", line 78, in ban_middleware
    return await handler(request)
  File "/usr/src/homeassistant/homeassistant/components/http/auth.py", line 181, in auth_middleware
    return await handler(request)
  File "/usr/src/homeassistant/homeassistant/components/http/view.py", line 137, in handle
    result = await result
  File "/usr/src/homeassistant/homeassistant/components/config/config_entries.py", line 215, in post
    return await super().post(request, flow_id)
  File "/usr/src/homeassistant/homeassistant/components/http/data_validator.py", line 62, in wrapper
    result = await method(view, request, *args, **kwargs)
  File "/usr/src/homeassistant/homeassistant/helpers/data_entry_flow.py", line 110, in post
    result = await self._flow_mgr.async_configure(flow_id, data)
  File "/usr/src/homeassistant/homeassistant/data_entry_flow.py", line 252, in async_configure
    result = await self._async_handle_step(flow, cur_step["step_id"], user_input)
  File "/usr/src/homeassistant/homeassistant/data_entry_flow.py", line 325, in _async_handle_step
    result: FlowResult = await getattr(flow, method)(user_input)
  File "/usr/src/homeassistant/homeassistant/components/upnp/config_flow.py", line 295, in async_step_init
    coordinator = self.hass.data[DOMAIN][self.config_entry.entry_id]
KeyError: '6fe907fbd696a41bf919cf5ca58dab68'
2021-12-15 10:53:24 ERROR (MainThread) [aiohttp.server] Error handling request
Traceback (most recent call last):
  File "/usr/local/lib/python3.9/site-packages/aiohttp/web_protocol.py", line 435, in _handle_request
    resp = await request_handler(request)
  File "/usr/local/lib/python3.9/site-packages/aiohttp/web_app.py", line 504, in _handle
    resp = await handler(request)
  File "/usr/local/lib/python3.9/site-packages/aiohttp/web_middlewares.py", line 117, in impl
    return await handler(request)
  File "/usr/src/homeassistant/homeassistant/components/http/security_filter.py", line 60, in security_filter_middleware
    return await handler(request)
  File "/usr/src/homeassistant/homeassistant/components/http/forwarded.py", line 98, in forwarded_middleware
    return await handler(request)
  File "/usr/src/homeassistant/homeassistant/components/http/request_context.py", line 28, in request_context_middleware
    return await handler(request)
  File "/usr/src/homeassistant/homeassistant/components/http/ban.py", line 78, in ban_middleware
    return await handler(request)
  File "/usr/src/homeassistant/homeassistant/components/http/auth.py", line 181, in auth_middleware
    return await handler(request)
  File "/usr/src/homeassistant/homeassistant/components/http/view.py", line 137, in handle
    result = await result
  File "/usr/src/homeassistant/homeassistant/components/config/config_entries.py", line 215, in post
    return await super().post(request, flow_id)
  File "/usr/src/homeassistant/homeassistant/components/http/data_validator.py", line 62, in wrapper
    result = await method(view, request, *args, **kwargs)
  File "/usr/src/homeassistant/homeassistant/helpers/data_entry_flow.py", line 110, in post
    result = await self._flow_mgr.async_configure(flow_id, data)
  File "/usr/src/homeassistant/homeassistant/data_entry_flow.py", line 252, in async_configure
    result = await self._async_handle_step(flow, cur_step["step_id"], user_input)
  File "/usr/src/homeassistant/homeassistant/data_entry_flow.py", line 325, in _async_handle_step
    result: FlowResult = await getattr(flow, method)(user_input)
  File "/usr/src/homeassistant/homeassistant/components/upnp/config_flow.py", line 295, in async_step_init
    coordinator = self.hass.data[DOMAIN][self.config_entry.entry_id]
KeyError: '6fe907fbd696a41bf919cf5ca58dab68'
2021-12-15 10:59:11 ERROR (MainThread) [homeassistant.components.hassio.handler] Client error on /homeassistant/restart request Server disconnected
